File: li2btl/1.csv
Time [s],Strain,Stress [MPa],Displacement [nm],Load [mN]
0,0,3.029284126,0,0.017862038
0.25,0.000198231,4.319039276,1.129918744,0.025467022
0.5,0.000682569,5.110621614,3.890644166,0.030134552
0.75,0.00081756,6.184833891,4.660091602,0.036468596
1,0.000954055,8.493703962,5.438112589,0.050082745
1.25,0.001100354,9.111871468,6.27201823,0.053727742
1.5,0.001304896,10.89150559,7.437905523,0.064221275
1.75,0.001576764,13.51131704,8.987553671,0.079668876
2,0.001836094,14.95315171,10.46573446,0.08817059
2.25,0.002031658,16.37456183,11.58044935,0.096551871
2.5,0.0022678,17.59806318,12.9264579,0.103766192
2.75,0.002397449,17.61517941,13.66545666,0.103867117
3,0.002552223,16.66771077,14.54767008,0.098280411
3.25,0.00291229,19.93560419,16.60005126,0.117549398
3.5,0.003188974,32.22457632,18.17715249,0.190010772
3.75,0.003233279,32.05064363,18.42969229,0.188985186
4,0.003273791,26.87475205,18.66060825,0.158465773
4.25,0.003564856,30.72067554,20.31968037,0.181143089
4.5,0.003809241,33.08766061,21.71267214,0.19509991
4.75,0.004083696,37.33240527,23.27706986,0.220128857
5,0.004090878,34.95866794,23.31800481,0.206132221
5.25,0.0046371,37.52555773,26.43147138,0.221267772
5.5,0.005020667,47.01479787,28.61779949,0.277220652
5.75,0.005100743,49.2055389,29.07423422,0.290138258
6,0.005067967,42.4452919,28.88741255,0.250276764
6.25,0.005406659,46.20296742,30.817955,0.27243373
6.5,0.005550852,53.06259613,31.63985427,0.312881224
6.75,0.005792866,54.97105602,33.01933843,0.324134372
7,0.00600008,54.97313483,34.20045555,0.32414663
7.25,0.006181937,56.49323774,35.23704261,0.333109848
7.5,0.006358927,63.07659254,36.24588588,0.371928305
7.75,0.006631724,67.18871332,37.80082921,0.396175242
8,0.006920938,65.51313105,39.44934769,0.386295246
8.25,0.007051688,68.59530453,40.19461929,0.404469144
8.5,0.007282639,66.33925055,41.51104455,0.391166422
8.75,0.00761661,69.94971046,43.41467889,0.412455338
9,0.007739764,74.97337819,44.11665726,0.44207717
9.25,0.007883711,77.57367587,44.93715545,0.457409708
9.5,0.00804552,80.47795817,45.85946673,0.474534679
9.75,0.008273748,82.99987134,47.16036317,0.489405027
10,0.008488657,81.25508978,48.38534594,0.479117001
10.25,0.00866609,84.89056684,49.39671096,0.500553429
10.5,0.008911912,90.54596142,50.79789761,0.53390021
10.75,0.00904507,93.25648187,51.5568981,0.549882672
11,0.009372404,102.6369526,53.42270438,0.605194198
11.25,0.009529115,102.0380383,54.3159567,0.601662727
11.5,0.00973157,100.3888684,55.46994913,0.59193847
11.75,0.01008574,106.7389493,57.48871638,0.629381438
12,0.010285746,113.5131205,58.62875235,0.669325036
12.25,0.010482658,111.7129175,59.75115211,0.658710219
12.5,0.010681336,119.7058758,60.88361703,0.70584034
12.75,0.010773251,121.8841567,61.40753196,0.718684476
13,0.010821036,114.6850727,61.6799074,0.676235399
13.25,0.011112754,119.0320564,63.34269708,0.701867194
13.5,0.011123733,127.1835665,63.40527538,0.749932208
13.75,0.0116768,135.0249878,66.55776207,0.796168799
14,0.011909789,124.986001,67.88579988,0.736974362
14.25,0.012021347,127.6959789,68.52167547,0.752953625
14.5,0.012357683,145.7364363,70.4387949,0.859328375
14.75,0.012449894,146.71089,70.96439425,0.865074198
15,0.012535239,141.6609563,71.45086046,0.835297489
15.25,0.012783305,144.8609681,72.864837,0.854166216
15.5,0.013058885,151.0853044,74.43564288,0.890867737
15.75,0.013248685,155.1313652,75.51750518,0.914725153
16,0.013502142,153.1761953,76.96220722,0.903196581
16.25,0.013649724,157.9133381,77.80342576,0.931128932
16.5,0.014024637,167.178664,79.94043306,0.985761511
16.75,0.013960966,166.1546906,79.57750381,0.979723698
17,0.014144969,162.614177,80.62632229,0.958847218
17.25,0.014547624,166.9274621,82.92145567,0.98428031
17.5,0.014695981,172.0897803,83.76708919,1.014719689
17.75,0.014970048,177.1681525,85.32927564,1.044664083
18,0.015121043,180.5703363,86.18994761,1.064724908
18.25,0.015256469,183.7632364,86.96187592,1.0835517
18.5,0.015327048,182.4277596,87.36417628,1.075677121
18.75,0.015769293,189.9463995,89.8849716,1.120010445
19,0.015937031,196.0891539,90.84107625,1.156230921
19.25,0.016239477,200.6948355,92.56502171,1.183388117
19.5,0.016499214,198.3151685,94.04552005,1.169356517
19.75,0.016608894,203.3387781,94.67069782,1.198978006
20,0.016775213,210.7098149,95.61871531,1.242440994
20.25,0.016961888,213.5056572,96.68276078,1.258926554
20.5,0.017072167,213.0916683,97.31135385,1.256485487
20.75,0.017359153,216.2345922,98.94717076,1.275017597
21,0.017591455,221.4046229,100.2712949,1.305502451
21.25,0.01780596,224.7308251,101.4939719,1.325115254
21.5,0.018012722,217.7571862,102.6725182,1.283995504
21.75,0.018192825,221.7994101,103.6991042,1.307830296
22,0.018367795,235.8509001,104.6964311,1.390684279
22.25,0.018583377,239.0130084,105.9252463,1.409329508
22.5,0.01877505,243.5975678,107.0177874,1.436362158
22.75,0.018919365,246.6455389,107.8403778,1.454334383
23,0.019246693,242.4151448,109.7061506,1.429390053
23.25,0.01938908,244.9030881,110.5177569,1.4440601
23.5,0.019651727,258.4611723,112.0148415,1.524004737
23.75,0.019910261,260.502508,113.4884863,1.536041381
24,0.019968449,257.1314367,113.8201612,1.516164011
24.25,0.020368354,264.8106438,116.09962,1.561444111
24.5,0.020521483,265.2797354,116.9724521,1.564210089
24.75,0.020602958,268.8521948,117.4368609,1.585274936
25,0.020818064,270.926609,118.6629641,1.597506626
25.25,0.020979226,273.4865033,119.5815907,1.612600928
25.5,0.021357131,277.4004052,121.7356494,1.635679076
25.75,0.021467019,279.5951963,122.3620075,1.648620563
26,0.021705104,284.7626303,123.7190912,1.679090107
26.25,0.021893605,288.6712227,124.7935495,1.702136947
26.5,0.022072874,292.53354,125.8153846,1.724910928
26.75,0.022362648,295.7932171,127.4670913,1.744131469
27,0.022537909,296.922192,128.4660821,1.750788418
27.25,0.022797115,302.9503054,129.9435575,1.786332919
27.5,0.022977458,300.16955,130.9715104,1.769936319
27.75,0.023179819,303.4523839,132.1249686,1.789293403
28,0.023357475,317.6493843,133.1376063,1.87300538
28.25,0.023490983,320.7016767,133.8986054,1.891003086
28.5,0.02380084,316.2632584,135.6647882,1.864832151
28.75,0.024033333,320.2500608,136.9899994,1.888340153
29,0.024119635,327.6415803,137.4819171,1.931923917
29.25,0.024275587,328.9212588,138.3708457,1.939469484
29.5,0.024486764,325.7208895,139.5745572,1.920598649
29.75,0.024745093,332.6907603,141.0470297,1.961696181
30,0.024917427,333.6870919,142.0293321,1.967571006
30.25,0.025189487,336.8244156,143.5800777,1.986070094
30.5,0.025297735,341.0720863,144.1970922,2.011116295
30.75,0.02573775,350.2502882,146.7051738,2.065235151
31,0.025725127,354.3053985,146.6332235,2.089145928
31.25,0.025957558,356.2771861,147.9580815,2.100772485
31.5,0.026154531,352.2981069,149.0808282,2.077310022
31.75,0.026438332,357.6092297,150.6984949,2.10862682
32,0.026543464,364.8560721,151.2977436,2.151357502
32.25,0.02690797,370.0701299,153.3754294,2.182101961
32.5,0.026891851,361.4383437,153.2835483,2.13120502
32.75,0.027226108,366.8790286,155.1888166,2.163285775
33,0.027444873,373.674632,156.435777,2.203355746
33.25,0.02763855,376.0632431,157.539737,2.217440085
33.5,0.027802267,376.6460843,158.4729191,2.220876782
33.75,0.028053474,378.7349933,159.9048037,2.23319394
34,0.028170598,381.3140719,160.572411,2.248401362
34.25,0.028490121,390.2441756,162.3936869,2.301057319
34.5,0.028805821,396.6558209,164.1931788,2.338863298
34.75,0.028795354,395.9798398,164.1335161,2.334877406
35,0.028937723,390.6798119,164.9450219,2.303626029
35.25,0.02924741,397.4253422,166.710239,2.343400746
35.5,0.029450088,402.5247978,167.8655008,2.373469458
35.75,0.029747237,403.9682409,169.5592523,2.381980655
36,0.029970004,408.8047547,170.8290243,2.410498943
36.25,0.030091687,412.8697479,171.5226162,2.434467993
36.5,0.030310932,416.4287007,172.7723106,2.455453199
36.75,0.030662645,417.8848752,174.7770781,2.464039467
37,0.030725992,424.1644004,175.1381538,2.501066406
37.25,0.030914863,424.8679673,176.2147195,2.505214957
37.5,0.030972567,423.270382,176.5436342,2.495794866
37.75,0.031302293,430.0992576,178.4230677,2.536061026
38,0.031600206,430.5673028,180.1211732,2.538820834
38.25,0.031914281,438.6308168,181.9114007,2.586366983
38.5,0.03195799,438.7647056,182.1605416,2.587156453
38.75,0.032202281,445.5304086,183.5530025,2.627050117
39,0.032368081,447.5454481,184.4980606,2.638931708
39.25,0.032575889,450.269262,185.682565,2.654992554
39.5,0.03272272,449.2316075,186.5195018,2.648874071
39.75,0.032866987,449.6094088,187.3418284,2.65110176
40,0.033207443,462.0440657,189.2824239,2.724422157
40.25,0.033349702,463.0926213,190.093301,2.730604919
40.5,0.033670883,459.9332367,191.9240331,2.711975749
40.75,0.033884708,461.1472428,193.142838,2.719134081
41,0.033980757,468.7861627,193.6903151,2.764176631
41.25,0.034239202,471.3215437,195.1634494,2.779126391
41.5,0.034537974,466.844466,196.8664521,2.752727503
41.75,0.034745777,469.7924266,198.0509309,2.770110021
42,0.034798917,481.6326014,198.3538277,2.839925082
42.25,0.034997545,484.0190227,199.4860057,2.853996508
42.5,0.035283644,484.6145178,201.1167695,2.857507819
42.75,0.035425583,487.2614393,201.9258219,2.873115272
43,0.035719586,482.1672071,203.6016405,2.84307736
43.25,0.035852815,485.3821983,204.3610428,2.862034412
43.5,0.036193947,494.1478011,206.3054977,2.913720397
43.75,0.036419606,498.8031295,207.5917543,2.941170332
44,0.036405539,499.5623697,207.511573,2.945647158
44.25,0.036668644,501.833995,209.0112712,2.959041695
44.5,0.036953503,500.6426721,210.6349697,2.952017113
44.75,0.03711198,504.5380098,211.5382862,2.974985797
45,0.037312503,512.9582945,212.6812697,3.024635629
45.25,0.037673189,515.2863101,214.7371793,3.038362669
45.5,0.037678328,512.0597222,214.7664688,3.019337238
45.75,0.038054985,520.8470867,216.9134169,3.071151539
46,0.03819383,519.4732024,217.7048319,3.063050492
46.25,0.038395658,522.9105381,218.8552489,3.083318589
46.5,0.038587573,529.7994666,219.9491678,3.123938847
46.75,0.038730164,532.9494829,220.7619362,3.142512777
47,0.038988824,529.9212494,222.2362988,3.124656934
47.25,0.039127914,532.5541605,223.0291094,3.140181776
47.5,0.039502107,537.2738048,225.1620127,3.168010948
47.75,0.039602605,539.3077381,225.7348477,3.180003944
48,0.0397683,535.0798049,226.6793086,3.155074126
48.25,0.040047884,537.7529837,228.2729389,3.170836405
48.5,0.040217886,545.6456796,229.2419504,3.217375333
48.75,0.04058238,550.5623801,231.3195655,3.246366438
49,0.040799707,546.8533932,232.5583274,3.224496562
49.25,0.040843622,548.4090549,232.8086441,3.233669452
49.5,0.041059569,559.6846674,234.0395445,3.300155596
49.75,0.041388123,563.9887673,235.9122991,3.325534529
50,0.041632239,559.0713217,237.3037634,3.296539031
50.25,0.041689793,561.4332491,237.6318179,3.31046603
50.5,0.041888513,561.9722764,238.7645245,3.31364438
50.75,0.042109844,563.643393,240.0261118,3.323498045
51,0.042379968,569.2786537,241.5658174,3.356726107
51.25,0.04247812,569.8079725,242.125283,3.359847212
51.5,0.042784258,572.3731958,243.870273,3.374972936
51.75,0.042868832,575.1533418,244.3523424,3.391365943
52,0.04294588,581.618742,244.7915153,3.429488886
52.25,0.043421228,584.1675714,247.5010023,3.444517944
52.5,0.043615338,576.5691042,248.607424,3.399713923
52.75,0.043800693,578.574571,249.6639477,3.411539068
53,0.044002545,585.1251768,250.8145085,3.450164422
53.25,0.044188982,585.7758414,251.8771954,3.454001036
53.5,0.044427794,590.7640084,253.2384238,3.48341354
53.75,0.044624285,592.8783609,254.3584247,3.495880725
54,0.044731717,594.0474872,254.970785,3.502774426
54.25,0.045019684,595.6871338,256.612199,3.512442528
54.5,0.045259518,603.7520818,257.9792528,3.559997133
54.75,0.045490152,603.838281,259.2938673,3.560505403
55,0.045741554,604.3295994,260.7268561,3.56340244
55.25,0.045877244,602.1098987,261.5002892,3.550314074
55.5,0.046112862,611.3565829,262.8433133,3.604836734
55.75,0.046180683,610.6323309,263.2298909,3.600566214
56,0.046440009,604.3688227,264.7080541,3.563633718
56.25,0.046786478,609.015334,266.6829242,3.591031664
56.5,0.046894857,619.1258368,267.3006866,3.650647792
56.75,0.047233002,622.2848058,269.2281098,3.669274511
57,0.047238937,612.1444908,269.2619433,3.609482597
57.25,0.047629645,617.7031304,271.4889775,3.642258867
57.5,0.047767532,630.9920331,272.274933,3.720616287
57.75,0.047963028,630.5626192,273.3892622,3.718084267
58,0.048258097,623.5898523,275.0711553,3.676969659
58.25,0.048504696,622.3618853,276.4767669,3.669729007
58.5,0.048569114,622.9496485,276.8439471,3.673194727
58.75,0.048871422,629.462312,278.5671047,3.711596355
59,0.049059038,633.6508601,279.6365175,3.736293941
59.25,0.049253844,636.2843718,280.74691,3.751822326
59.5,0.049591654,641.6985475,282.6724264,3.78374677
59.75,0.049629786,639.767736,282.8897805,3.772361827
60,0.05017932,641.0341986,286.0221253,3.779829467
60.25,0.050133174,641.9784224,285.759092,3.78539704
60.5,0.050518947,651.6627228,287.9579977,3.842500084
60.75,0.05078159,653.4101892,289.4550646,3.852803942
61,0.050717136,655.2141235,289.0876738,3.863440759
61.25,0.050999769,659.793509,290.698685,3.890442901
61.5,0.051203723,646.0117538,291.8612237,3.809179398
61.75,0.051270063,647.6207442,292.23936,3.818666738
62,0.051516107,649.4340381,293.6418094,3.829358744
62.25,0.051805478,653.28562,295.2912254,3.852069425
62.5,0.051980083,662.0687794,296.2864742,3.903858931
62.75,0.052159974,664.1593743,297.3118509,3.91618603
63,0.052455988,657.2455557,298.9991336,3.875419008
63.25,0.052540034,657.9436386,299.4781941,3.879535223
63.5,0.052782376,663.9984357,300.8595411,3.915237063
63.75,0.053023957,665.5324327,302.2365537,3.924282208
64,0.053243821,668.5215524,303.4897817,3.941907418
64.25,0.0535035,672.2486299,304.9699503,3.963883964
64.5,0.053772536,676.7491658,306.5034551,3.990421172
64.75,0.053971719,680.1954348,307.6388008,4.010741944
65,0.05420697,669.3074149,308.9797292,3.946541221
65.25,0.054410207,673.3441935,310.1381783,3.970343906
65.5,0.054421575,687.3626632,310.2029769,4.053003185
65.75,0.054729517,688.2310023,311.9582475,4.058123308
66,0.055039631,675.9872888,313.7258955,3.985928799
66.25,0.055343212,679.7880031,315.4563072,4.008339541
66.5,0.055493957,683.0192525,316.3155555,4.027392458
66.75,0.05558496,682.1355379,316.8342715,4.022181675
67,0.055744107,691.6451638,317.7414083,4.078254758
67.25,0.05604302,693.7365726,319.4452161,4.090586657
67.5,0.056270485,690.7627529,320.7417645,4.073051662
67.75,0.056469586,691.2853669,321.8766397,4.076133232
68,0.056730603,686.4308033,323.3644397,4.047508515
68.25,0.056931646,690.8146248,324.5103847,4.073357522
68.5,0.057126013,694.0839135,325.6182753,4.092634736
68.75,0.057233279,697.575973,326.2296903,4.113225509
69,0.057633978,695.3752048,328.5136766,4.100248778
69.25,0.05788914,699.4473873,329.9680976,4.12426022
69.5,0.057864981,700.0406733,329.8303919,4.127758504
69.75,0.0583128,705.4334361,332.3829589,4.159556689
70,0.058487793,710.0893265,333.3804175,4.187009938
70.25,0.058486485,708.4352733,333.372965,4.177256887
70.5,0.058966963,698.7580954,336.1116913,4.120195841
70.75,0.059178168,703.7642066,337.3155562,4.149714152
71,0.059208801,710.5805833,337.4901654,4.189906612
71.25,0.059336587,711.6543886,338.2185436,4.196238257
71.5,0.059563596,711.0211557,339.5124974,4.192504427
71.75,0.059770662,716.6060526,340.6927756,4.225435522
72,0.060041104,712.644278,342.2342906,4.202075096
72.25,0.060344108,715.470699,343.9614181,4.218740961
72.5,0.060574852,715.4019508,345.2766569,4.21833559
72.75,0.060650938,715.4162184,345.710347,4.218419718
73,0.060943465,725.7362763,347.3777482,4.279271477
73.25,0.061264953,727.9567821,349.2102331,4.292364591
73.5,0.061379416,718.1222539,349.8626709,4.234375735
73.75,0.06162307,719.1686392,351.2514962,4.240545699
74,0.061757782,727.6056084,352.0193587,4.290293911
74.25,0.061984719,728.2120715,353.3128966,4.293869893
74.5,0.062163842,717.7387241,354.3338998,4.232114269
74.75,0.062486703,723.6285164,356.1742098,4.266843166
75,0.062674249,730.7061878,357.2432165,4.308576338
75.25,0.062807423,730.5862426,358.0023125,4.307869087
75.5,0.063108152,729.2444678,359.7164658,4.299957372
75.75,0.063298086,729.0603423,360.7990919,4.298871684
76,0.063534649,738.1806229,362.1474988,4.352649011
76.25,0.063588289,740.3096834,362.4532451,4.36520292
76.5,0.063985725,743.1324807,364.7186297,4.381847418
76.75,0.064133381,742.9845147,365.5602699,4.380974943
77,0.064302216,738.4189177,366.5226297,4.354054105
77.25,0.064598976,743.0125074,368.2141633,4.381140001
77.5,0.064794634,744.377159,369.3294161,4.389186608
77.75,0.065144384,749.353234,371.3229911,4.418527812
78,0.065092453,741.3072679,371.0269801,4.371085133
78.25,0.065344235,743.9857951,372.4621393,4.386878948
78.5,0.065681832,744.2200432,374.3864404,4.388260182
78.75,0.065893986,745.858062,375.5957212,4.397918686
79,0.066246852,753.1588531,377.6070556,4.440967474
79.25,0.06637836,751.3352413,378.3566526,4.430214629
79.5,0.066671801,754.5493604,380.0292657,4.449166539
79.75,0.066880006,754.107312,381.2160361,4.44656002
80,0.067001061,753.4498757,381.9060502,4.442683477
80.25,0.067152341,755.2992711,382.7683425,4.453588354
80.5,0.067516205,750.6314158,384.8423691,4.426064554
80.75,0.06760916,750.6417497,385.3722116,4.426125487
81,0.067798073,760.3954625,386.4490183,4.483637818
81.25,0.067982082,762.1575207,387.4978701,4.494027715
81.5,0.068234937,754.5924033,388.9391424,4.449420339
81.75,0.068485832,754.4779033,390.3692424,4.448745195
82,0.068511426,760.4238922,390.5151275,4.483805453
82.25,0.0689237,761.2586878,392.8650878,4.488727787
82.5,0.069060359,761.4245505,393.6440483,4.489705789
82.75,0.069280348,760.6952214,394.8979822,4.485405333
83,0.06946952,772.0159462,395.9762625,4.55215748
83.25,0.069777948,771.9722345,397.7343059,4.551899736
83.5,0.069888746,765.547384,398.3658542,4.514015893
83.75,0.070088635,764.6764784,399.5052208,4.508880637
84,0.070285843,773.9566867,400.629305,4.56360097
84.25,0.07060415,773.3785457,402.4436555,4.560191987
84.5,0.070714526,771.8172944,403.0727992,4.550986139
84.75,0.070983943,776.1671072,404.6084733,4.576634615
85,0.07121867,772.4628679,405.9464218,4.554792734
85.25,0.071387062,775.3812187,406.9062517,4.572000659
85.5,0.071763339,780.0953984,409.0510342,4.599797609
85.75,0.071921196,779.6021336,409.95082,4.596889095
86,0.072074952,776.5733576,410.8272266,4.579030052
86.25,0.07232141,774.4972876,412.232037,4.566788599
86.5,0.072495663,787.3760136,413.225279,4.64272743
86.75,0.072740718,788.0549896,414.6220931,4.646730982
87,0.072867755,776.8095789,415.3462012,4.580422921
87.25,0.073201718,781.3231563,417.2497925,4.607037028
87.5,0.073340867,789.9366603,418.0429436,4.657826169
87.75,0.073813019,791.7320682,420.7342088,4.668412711
88,0.073879728,788.4981553,421.1144503,4.649344089
88.25,0.074149633,789.3092514,422.6529071,4.654126681
88.5,0.074268275,783.863752,423.3291667,4.622017537
88.75,0.074457158,783.8735239,424.4058002,4.622075157
89,0.074810647,795.1987444,426.4206865,4.688853813
89.25,0.074772415,789.9632845,426.2027642,4.657983157
89.5,0.075131932,790.619937,428.2520106,4.661855079
89.75,0.07537184,791.3866378,429.6194894,4.666375896
90,0.075691533,787.5163279,431.4417366,4.643554788
90.25,0.075733333,786.9961857,431.6799988,4.640487792
90.5,0.075907577,797.0254941,432.6731911,4.699625161
90.75,0.076213672,797.5954101,434.417929,4.702985645
91,0.076357209,786.4702988,435.236091,4.637386924
91.25,0.076679291,793.4051922,437.0719571,4.678278212
91.5,0.076714155,799.8450713,437.2706817,4.716250671
91.75,0.077009143,799.3771919,438.9521136,4.713491841
92,0.077132727,796.9208844,439.6565461,4.699008334
92.25,0.077458512,799.4274113,441.5135212,4.713787958
92.5,0.077827189,792.1156823,443.6149798,4.670674675
92.75,0.07784736,793.1032356,443.7299517,4.676497738
93,0.078292101,813.273097,446.2649736,4.795428424
93.25,0.078308323,808.6714955,446.357439,4.768295286
93.5,0.078655856,805.3783824,448.3383818,4.748877593
93.75,0.078766667,807.6639019,448.9699995,4.762354056
94,0.079113073,799.7882888,450.9445176,4.715915856
94.25,0.079153588,796.809392,451.1754533,4.698350924
94.5,0.079378249,814.7059669,452.45602,4.803877277
94.75,0.079551833,813.9738861,453.4454471,4.799560596
95,0.079834393,802.2611526,455.0560415,4.730496986
95.25,0.080127692,806.9812233,456.7278462,4.758328672
95.5,0.080308561,818.2236023,457.7587974,4.824618857
95.75,0.080472865,819.7544407,458.6953296,4.833645377
96,0.080826934,812.7746977,460.7135214,4.792489634
96.25,0.080876291,809.5278015,460.9948602,4.773344456
96.5,0.081016494,811.0424979,461.7940186,4.782275796
96.75,0.081410151,814.8868324,464.0378581,4.804943742
97,0.081668632,822.0454849,465.5112016,4.847154416
97.25,0.08183732,821.1945387,466.4727263,4.84213685
97.5,0.082032727,811.0543399,467.5865422,4.782345622
97.75,0.082289905,812.7519271,469.0524558,4.792355369
98,0.082428735,825.9511091,469.8437902,4.870183755
98.25,0.082656778,827.1559493,471.1436349,4.877288041
98.5,0.082930104,820.684572,472.7015927,4.839129854
98.75,0.083053215,818.5076001,473.4033235,4.826293437
99,0.083248438,813.3126405,474.5160943,4.79566159
99.25,0.083710659,819.0742465,477.1507559,4.829634642
99.5,0.083644437,822.7773145,476.7732887,4.851469617
99.75,0.083934819,829.0979988,478.428467,4.888739249
100,0.084246957,823.6806171,480.2076555,4.8567959
100.25,0.08431041,823.017038,480.5693387,4.852883136
100.5,0.084596815,826.5719602,482.201844,4.873844575
100.75,0.084930703,829.5958055,484.1050064,4.891674544
101,0.084996818,833.772843,484.4818653,4.916304259
101.25,0.085083793,835.2737228,484.9776203,4.925154129
101.5,0.085629981,831.3971926,488.0908908,4.902296342
101.75,0.085572015,828.8999391,487.7604848,4.887571399
102,0.085882247,826.203711,489.5288063,4.871673211
102.25,0.086060492,826.857418,490.5448041,4.875527765
102.5,0.086416062,835.7824834,492.5715556,4.928154014
102.75,0.086605136,838.0922643,493.6492768,4.941773533
103,0.086780098,830.496607,494.6465574,4.89698608
103.25,0.087028677,827.4125645,496.0634567,4.878801161
103.5,0.087318237,833.6879428,497.7139511,4.915803648
103.75,0.087529945,828.0983476,498.9206893,4.882844851
104,0.087745177,825.96705,500.1475116,4.87027775
104.25,0.087941913,827.1792927,501.2689067,4.877425684
104.5,0.088150945,830.8966617,502.4603875,4.899344984
104.75,0.088395489,831.1000986,503.8542888,4.900544541
105,0.088524724,835.9415151,504.590928,4.929091736
105.25,0.088701798,839.0613209,505.6002477,4.947487532
105.5,0.08907325,836.849139,507.7175264,4.9344435
105.75,0.089057506,834.8843188,507.6277835,4.922858026
106,0.089364516,831.8697469,509.3777414,4.905082738
106.25,0.089617238,834.0576394,510.8182561,4.917983548
106.5,0.089808305,834.3770737,511.9073402,4.919867078
106.75,0.090131432,833.2712276,513.7491642,4.913346506
107,0.090283248,834.2012473,514.6145152,4.918830325
107.25,0.090447321,832.5643438,515.5497313,4.909178397
107.5,0.090792652,834.3260337,517.5181145,4.919566123
107.75,0.090931359,835.0614389,518.3087441,4.923902407
108,0.091204386,842.9999253,519.8650015,4.970711337
108.25,0.091380905,842.2843547,520.8711577,4.966492006
108.5,0.091568312,837.0119406,521.9393806,4.935403453
108.75,0.091792767,836.4406208,523.2187724,4.932034691
109,0.092084651,837.2166425,524.8825089,4.936610468
109.25,0.09221356,836.3249441,525.6172892,4.931352608
109.5,0.092398432,846.5814029,526.6710603,4.991829359
109.75,0.092621875,847.6306174,527.9446857,4.998016005
110,0.092793129,837.301075,528.920838,4.937108321
110.25,0.092988691,838.190885,530.0355386,4.942355046
110.5,0.093233862,853.976349,531.4330162,5.035433327
110.75,0.093545212,856.7483949,533.2077087,5.051778573
111,0.093777375,844.7763434,534.5310375,4.981185906
111.25,0.094017605,844.391693,535.9003472,4.978917832
111.5,0.09415483,845.9696008,536.6825324,4.988221895
111.75,0.094240076,843.5514876,537.1684324,4.973963599
112,0.094703455,849.5592927,539.8096938,5.009388353
112.25,0.094941505,848.6714118,541.1665792,5.004153003
112.5,0.095124916,856.0109785,542.212023,5.04743043
112.75,0.095274793,854.0230403,543.0663201,5.035708641
113,0.095550352,851.2803822,544.6370047,5.01953668
113.25,0.095670733,850.8455812,545.3231762,5.016972896
113.5,0.095920886,848.9211257,546.7490505,5.00562543
113.75,0.096163159,846.0195089,548.1300079,4.988516176
114,0.096477968,854.5894314,549.9244182,5.039048341
114.25,0.096399778,848.8468072,549.4787352,5.005187214
114.5,0.096863428,855.6753922,552.1215406,5.04545166
114.75,0.097005613,853.946462,552.9319961,5.0352571
115,0.097205457,855.4087793,554.0711076,5.043879589
115.25,0.097376493,854.2336177,555.0460096,5.036950301
115.5,0.097629042,859.3838827,556.4855377,5.067318608
115.75,0.097785293,860.3208204,557.3761721,5.072843219
116,0.09802391,850.4434083,558.7362863,5.014601501
116.25,0.098286455,854.4818341,560.232793,5.038413898
116.5,0.098410121,860.0429929,560.9376904,5.071205022
116.75,0.098676094,859.9647687,562.453736,5.070743777
117,0.098939097,851.9991443,563.9528514,5.023774829
117.25,0.099118094,852.0502885,564.9731374,5.024076398
117.5,0.099407973,854.8547735,566.6254459,5.040612918
117.75,0.099761893,856.9315324,568.6427913,5.052858434
118,0.099692197,866.0283461,568.2455223,5.10649739
118.25,0.099989299,866.4683318,569.9390071,5.109091745
118.5,0.100228214,864.6170868,571.3008175,5.098175962
118.75,0.100544438,867.4454456,573.1032961,5.114853253
119,0.100601562,856.5908723,573.4289031,5.050849748
119.25,0.100875136,856.8692832,574.9882759,5.052491385
119.5,0.101096207,872.9288701,576.2483799,5.14718602
119.75,0.101456391,870.4202029,578.3014306,5.132393776
120,0.10141304,861.263657,578.0543306,5.078402614
120.25,0.101779649,860.5313631,580.1440004,5.074084675
120.5,0.101993915,861.2750427,581.3653178,5.078469749
120.75,0.102284868,864.4857125,583.0237494,5.09740132
121,0.102382088,875.236081,583.5779001,5.160790386
121.25,0.102734727,874.8008343,585.5879425,5.158223973
121.5,0.102900704,867.3637288,586.5340152,5.114371414
121.75,0.103035393,866.6753651,587.3017407,5.110312508
122,0.103422806,874.5781957,589.5099925,5.156911195
122.25,0.103567156,874.6334287,590.3327875,5.157236874
122.5,0.103901191,872.4733546,592.2367883,5.144500093
122.75,0.103876746,867.5929988,592.0974539,5.115723294
123,0.104115492,867.004878,593.4583044,5.112255466
123.25,0.104392042,867.3932598,595.0346402,5.114545542
123.5,0.104393931,875.256094,595.0454092,5.160908392
123.75,0.104773999,878.5643326,597.2117953,5.180415273
124,0.105007506,875.180995,598.542784,5.160465574
124.25,0.105274907,874.8289968,600.0669726,5.158390032
124.5,0.105519146,877.907159,601.4591305,5.176540278
124.75,0.105607656,877.6815061,601.9636398,5.175209726
125,0.105804008,870.759568,603.0828481,5.134394828
125.25,0.106091609,873.8983838,604.7221737,5.152902714
125.5,0.106596742,882.566941,607.6014283,5.204016474
125.75,0.106570725,877.7932036,607.4531323,5.175868345
126,0.106796499,879.8972275,608.7400416,5.188274628
126.25,0.107014907,877.6828171,609.9849673,5.175217456
126.5,0.107011496,878.6420203,609.9655285,5.180873355
126.75,0.107327712,880.9797056,611.7679563,5.194657412
127,0.107737342,872.3035047,614.1028501,5.143498581
127.25,0.107903071,873.2237772,615.0475033,5.148924927
127.5,0.108110455,890.0775571,616.2295938,5.248302486
127.75,0.108126305,884.6572105,616.3199378,5.216341655
128,0.108471327,881.2327138,618.2865634,5.196149263
128.25,0.108689504,882.120024,619.5301736,5.201381248
128.5,0.108947199,881.4037945,620.9990364,5.197158033
128.75,0.109163664,881.9820043,622.2328854,5.200567421
129,0.109467006,882.6246658,623.9619355,5.204356846
129.25,0.109600574,886.254155,624.7232698,5.225757967
129.5,0.109728183,884.0177117,625.4506407,5.212570879
129.75,0.109950421,882.9258179,626.7173971,5.206132576
130,0.110093117,887.4353065,627.5307681,5.232722573
130.25,0.110394723,889.8822651,629.2499184,5.247150955
130.5,0.110652251,881.0513299,630.7178279,5.195079741
130.75,0.110820197,883.1011532,631.6751215,5.207166432
131,0.111161157,888.6492705,633.6185952,5.239880658
131.25,0.111320532,887.9698013,634.5270325,5.235874198
131.5,0.111436418,880.6429573,635.1875838,5.19267179
131.75,0.111794599,881.6809906,637.2292131,5.198792507
132,0.111956448,894.1433388,638.1517544,5.272276186
132.25,0.112114489,895.3158951,639.0525863,5.279190111
132.5,0.112316167,887.5984269,640.2021536,5.233684406
132.75,0.112650006,894.1256045,642.1050325,5.272171616
133,0.112960451,889.7591759,643.8745719,5.246425166
133.25,0.113077594,889.4392291,644.5422857,5.244538613
133.5,0.113264597,893.5188528,645.608202,5.268593932
133.75,0.11343423,893.5977852,646.5751134,5.269059353
134,0.113736433,890.1888879,648.2976696,5.248958943
134.25,0.113932419,893.8840302,649.4147894,5.270747184
134.5,0.114094947,898.9834276,650.3411985,5.300815553
134.75,0.114396929,898.2425879,652.062495,5.296447225
135,0.114568031,902.4648539,653.037779,5.321343627
135.25,0.114797328,900.6302354,654.3447705,5.310525881
135.5,0.115130912,894.0082126,656.2461992,5.27147942
135.75,0.115242177,892.0231423,656.8804062,5.259774542
136,0.115522089,895.4212567,658.4759078,5.279811371
136.25,0.115675565,895.9967729,659.3507228,5.283204877
136.5,0.115729603,897.9337962,659.6587347,5.294626448
136.75,0.116119212,898.687223,661.8795086,5.299068996
137,0.116269627,893.642967,662.736874,5.269325766
137.25,0.116665005,895.3901816,664.9905279,5.279628138
137.5,0.116743171,899.7993884,665.4360743,5.305626829
137.75,0.117079714,900.6407143,667.3543705,5.31058767
138,0.117155132,897.8176371,667.7842501,5.293941521
138.25,0.1173649,899.0718915,668.9799302,5.301337176
138.5,0.117797075,903.9186757,671.4433285,5.329916022
138.75,0.117894946,904.285974,672.0011945,5.33208178
139,0.118016295,899.163973,672.6928833,5.301880131
139.25,0.118242127,902.9107386,673.980122,5.323972767
139.5,0.118550831,905.0965576,675.7397384,5.33686135
139.75,0.118609188,904.9803524,676.0723729,5.336176151
140,0.11897104,905.9109534,678.1349253,5.341663398
140.25,0.119027052,904.3737503,678.4541982,5.332599349
140.5,0.119496815,902.5772291,681.1318468,5.322006243
140.75,0.119580188,906.5524047,681.6070727,5.345445687
141,0.119802689,900.2229528,682.8753267,5.308124357
141.25,0.119961031,899.5634043,683.7778767,5.304235359
141.5,0.120167171,904.1154085,684.9528768,5.331076048
141.75,0.120459132,906.3411852,686.6170545,5.344200241
142,0.120662066,903.3286092,687.7737734,5.326436722
142.25,0.121004634,909.1984809,689.7264122,5.361048157
142.5,0.120939538,908.3751097,689.3553677,5.356193186
142.75,0.121415988,912.7713719,692.0711341,5.38211555
143,0.121329446,907.5379661,691.5778438,5.351257006
143.25,0.121215017,897.7646534,690.9255976,5.293629105
143.5,0.121045158,888.4269221,689.9574021,5.23856959
143.75,0.120791201,880.6322708,688.5098471,5.192608778
144,0.120508486,872.1288841,686.8983701,5.142468938
144.25,0.120312966,863.686674,685.7839046,5.092689825
144.5,0.120179409,860.0625826,685.0226337,5.071320532
144.75,0.119904688,850.0188482,683.4567206,5.012098101
145,0.119888247,847.8917169,683.3630072,4.999555567
145.25,0.119672901,840.6146747,682.1355383,4.956646813
145.5,0.119536319,831.220805,681.3570163,4.901256281
145.75,0.119262694,821.8092818,679.7973532,4.845761656
146,0.119065581,815.2898468,678.673814,4.807320098
146.25,0.118889258,808.9089847,677.6687734,4.769695631
146.5,0.118749335,802.5616855,676.8712088,4.732269065
146.75,0.118463723,797.239024,675.2432205,4.70088423
147,0.118251963,790.4937757,674.0361882,4.661111175
147.25,0.11808835,786.129033,673.1035936,4.635374665
147.5,0.117936924,781.0880713,672.240464,4.60565086
147.75,0.11759652,772.6424314,670.3001628,4.555851522
148,0.117638585,766.2988722,670.5399321,4.518447009
148.25,0.117360094,758.0789486,668.9525346,4.469978598
148.5,0.117118042,763.3063579,667.5728373,4.500801783
148.75,0.116909768,758.217978,666.3856777,4.470798378
149,0.116679405,740.9122334,665.0726074,4.36875583
149.25,0.116434219,731.0499363,663.6750488,4.310603236
149.5,0.116320376,736.0199266,663.0261409,4.339908562
149.75,0.116131887,727.4749351,661.9517563,4.289523401
150,0.115874612,718.4139622,660.4852907,4.23609578
150.25,0.115650694,714.1532994,659.2089539,4.210972972
150.5,0.115463153,712.9038808,658.1399698,4.203605832
150.75,0.115590779,713.0773979,658.867443,4.204628967
151,0.115275976,696.6283602,657.0730653,4.107637953
151.25,0.115021229,688.5521835,655.6210078,4.060017138
151.5,0.114804628,691.303243,654.3863822,4.076238638
151.75,0.114577318,683.0817111,653.0907131,4.027760742
152,0.114352205,681.0266276,651.8075696,4.015643035
152.25,0.114276822,674.6489629,651.3778878,3.97803742
152.5,0.11405779,666.7188973,650.1294011,3.931278143
152.75,0.113595352,657.6698226,647.4935051,3.877920679
153,0.113575263,662.5492008,647.3790019,3.906691715
153.25,0.11334313,657.285972,646.0558389,3.875657322
153.5,0.113220659,648.7734776,645.3577565,3.825463779
153.75,0.113082945,641.0842045,644.5727887,3.780124325
154,0.112779417,636.863015,642.8426743,3.755234269
154.25,0.112584478,632.8158604,641.7315258,3.731370403
154.5,0.112523674,626.4643755,641.3849415,3.693919157
154.75,0.112241186,620.1747069,639.7747626,3.656832407
155,0.112060119,618.4306036,638.7426785,3.64654838
155.25,0.111878383,611.8430544,637.7067804,3.607705191
155.5,0.111539802,609.132661,635.7768705,3.591723478
155.75,0.111409217,602.2123119,635.0325368,3.550917949
156,0.111226975,597.4473528,633.9937601,3.522821581
156.25,0.11106012,594.39604,633.0426835,3.504829652
156.5,0.110857686,582.9170842,631.8888093,3.437144502
156.75,0.110750734,579.1274261,631.2791823,3.414798953
157,0.110470192,567.1369265,629.6800942,3.344097509
157.25,0.110323822,564.3476447,628.8457879,3.327650633
157.5,0.109985664,570.1211489,626.9182849,3.361693843
157.75,0.109826479,563.9405598,626.0109281,3.325250275
158,0.109605088,562.1407056,624.7490001,3.314637516
158.25,0.10942471,559.673837,623.7208474,3.300091735
158.5,0.10922891,542.7898379,622.6047848,3.20053599
158.75,0.109026968,540.2667728,621.4537167,3.185658849
159,0.108885776,537.1656194,620.6489216,3.167373038
159.25,0.108723776,533.4787041,619.725526,3.145633307
159.5,0.108402843,525.4819003,617.8962073,3.098480511
159.75,0.108278417,526.5882609,617.1869754,3.105004116
160,0.10819751,517.6069127,616.7258048,3.052045999
160.25,0.107737923,506.9896439,614.1061637,2.989441748
160.5,0.107729791,501.2955231,614.0598082,2.95586662
160.75,0.10750303,496.1691814,612.7672698,2.925639375
161,0.107260768,506.1473316,611.3863772,2.984475092
161.25,0.107173999,501.605783,610.8917917,2.957696053
161.5,0.107016283,483.7968466,609.9928131,2.852686457
161.75,0.106671361,477.8360248,608.0267594,2.817538738
162,0.106496192,479.2937883,607.0282953,2.826134375
162.25,0.106306551,475.1280977,605.9473384,2.801571567
162.5,0.106118084,473.457825,604.8730787,2.791722879
162.75,0.105968405,469.7746884,604.0199057,2.770005429
163,0.105724844,462.4645484,602.6316111,2.726901515
163.25,0.105418817,452.3310545,600.8872586,2.667149822
163.5,0.105432774,448.8439277,600.9668121,2.646588134
163.75,0.105178058,443.5905624,599.5149282,2.615611901
164,0.104871709,450.8785639,597.7687425,2.658585276
164.25,0.104747223,445.6479679,597.0591687,2.6277433
164.5,0.104507636,434.9059621,595.6935277,2.564403544
164.75,0.104290411,429.8919941,594.4553411,2.534838906
165,0.104175453,424.1483623,593.80008,2.500971838
165.25,0.103901571,414.2218073,592.2389561,2.442440351
165.5,0.103566352,407.6338125,590.3282067,2.403594534
165.75,0.103446494,406.6577029,589.6450148,2.397838948
166,0.103376224,409.0492013,589.2444772,2.411940311
166.25,0.103119159,408.1683547,587.7792088,2.406746438
166.5,0.102909599,396.4352354,586.5847163,2.337562625
166.75,0.102686671,392.6853993,585.3140273,2.315451885
167,0.102464531,387.0525522,584.0478241,2.282238054
167.25,0.102386238,382.2323655,583.6015582,2.253816039
167.5,0.102189122,375.3327898,582.4779945,2.213132999
167.75,0.102064229,372.4227822,581.7661079,2.19597427
168,0.101683258,366.6706628,579.5945716,2.162057155
168.25,0.101580928,363.9074251,579.0112895,2.145763848
168.5,0.10133526,361.1843584,577.6109793,2.129707407
168.75,0.101204127,357.5642782,576.8635252,2.108361766
169,0.100841068,352.1552485,574.7940872,2.076467664
169.25,0.100744842,350.296446,574.2456001,2.065507319
169.5,0.100513912,334.5744561,572.9292981,1.972803309
169.75,0.100243717,332.0149989,571.3891844,1.957711584
170,0.100166795,339.8432431,570.9507322,2.003870476
170.25,0.099785145,331.0575752,568.7753285,1.952066178
170.5,0.099617999,321.5217608,567.8225942,1.895838675
170.75,0.099565756,320.1439621,567.5248107,1.887714547
171,0.09929537,317.6432206,565.9836088,1.872969036
171.25,0.099103662,310.8289861,564.8908752,1.832789208
171.5,0.098846419,312.315468,563.4245871,1.841554181
171.75,0.098776158,310.0871441,563.0241034,1.828414969
172,0.098475585,302.8360492,561.3108318,1.785659213
172.25,0.098266844,295.9756948,560.1210119,1.74520744
172.5,0.098194337,290.9133591,559.7077213,1.715357604
172.75,0.09792732,283.0858813,558.1857235,1.669203231
173,0.097639015,278.3044314,556.5423859,1.641009626
173.25,0.097474599,276.1926282,555.6052134,1.628557473
173.5,0.097269787,275.9092672,554.4377868,1.626886648
173.75,0.097143612,271.3909335,553.71859,1.600244495
174,0.096785066,275.9789617,551.6748751,1.627297598
174.25,0.09667531,274.1129506,551.049268,1.616294747
174.5,0.096514894,266.7517492,550.1348962,1.572889752
174.75,0.096217395,259.2023475,548.4391513,1.528375043
175,0.095946982,252.5538929,546.8977987,1.489172728
175.25,0.095959883,252.0271233,546.9713348,1.486066655
175.5,0.09578752,247.5907397,545.988863,1.459907717
175.75,0.095215437,237.145413,542.7279909,1.398317316
176,0.095263642,238.4288703,543.0027576,1.405885164
176.25,0.095058696,236.8259753,541.834567,1.396433766
176.5,0.094857748,227.8958048,540.6891661,1.343777415
176.75,0.094666826,224.214451,539.6009105,1.322070477
177,0.094499367,227.2603293,538.6463921,1.340030362
177.25,0.094293281,222.6694826,537.4717009,1.31296064
177.5,0.094013652,210.3148875,535.877814,1.240112323
177.75,0.094042858,209.7755997,536.0442906,1.236932436
178,0.09371092,208.5317426,534.1522468,1.229598089
178.25,0.09341851,204.7197803,532.4855046,1.207121024
178.5,0.093209291,194.5429181,531.2929586,1.147113611
178.75,0.092973975,190.6507497,529.9516547,1.124163615
179,0.092826567,195.3160384,529.111433,1.151672281
179.25,0.092601565,191.2210005,527.8289192,1.127526073
179.5,0.092458549,184.6564532,527.013732,1.088818513
179.75,0.092177722,177.4948852,525.4130181,1.046590648
180,0.092170149,178.3098376,525.3698503,1.051395978
180.25,0.091823313,169.7137653,523.3928845,1.000709622
180.5,0.091545742,170.3348395,521.8107305,1.004371759
180.75,0.091405023,166.8934257,521.0086297,0.984079616
181,0.091323362,158.1475992,520.5431647,0.932510242
181.25,0.091008219,153.1479129,518.7468496,0.903029815
181.5,0.090783122,148.3752026,517.4637945,0.874887742
181.75,0.090567093,148.7574995,516.2324278,0.877141939
182,0.090453797,146.1855628,515.5866437,0.861976629
182.25,0.0901879,141.6794179,514.0710297,0.835406348
182.5,0.089901258,142.9358233,512.4371697,0.842814686
182.75,0.089790974,139.4342017,511.808549,0.822167531
183,0.089573237,133.9554688,510.5674519,0.789862427
183.25,0.089517741,130.5327742,510.2511227,0.769680662
183.5,0.089176942,119.8864382,508.3085675,0.706905018
183.75,0.088930764,117.1308356,506.9053523,0.69065673
184,0.088806572,118.4537854,506.197463,0.698457445
184.25,0.0886884,114.4319968,505.5238788,0.674743148
184.5,0.088316813,115.7847502,503.4058356,0.682719599
184.75,0.088140166,114.3382949,502.3989482,0.674190639
185,0.087854129,100.8099474,500.7685334,0.594421344
185.25,0.087742753,99.9192373,500.1336934,0.589169311
185.5,0.087557767,99.46984457,499.0792711,0.586519487
185.75,0.087439974,96.69267408,498.4078497,0.570144026
186,0.087143267,88.77059228,496.7166225,0.523431825
186.25,0.086872952,87.51466266,495.1758262,0.516026292
186.5,0.086846935,81.4583454,495.0275315,0.480315488
186.75,0.086550533,76.72204656,493.3380391,0.452388114
187,0.086328084,76.26693729,492.0700778,0.449704583
187.25,0.086255519,75.49069375,491.6564584,0.445127498
187.5,0.085976976,74.25191377,490.0687655,0.437823087
187.75,0.085888898,71.55859242,489.566721,0.421942038
188,0.085532392,61.36779737,487.534637,0.361852471
188.25,0.085399954,58.37802948,486.7797378,0.344223439
188.5,0.085005802,55.54857681,484.5330717,0.327539697
188.75,0.084941321,54.99680946,484.1655295,0.324286226
189,0.084723698,49.74828867,482.925079,0.293338558
189.25,0.084565928,45.10858979,482.0257909,0.265980781
189.5,0.084348179,53.40101762,480.7846183,0.314876711
189.75,0.084115439,50.77970537,479.4580045,0.29942026
190,0.083887226,40.5476543,478.1571871,0.239087429
190.25,0.083686256,39.318544,477.011662,0.231840035
190.5,0.083613353,36.404874,476.5961119,0.214659711
190.75,0.083276258,33.81177631,474.6746682,0.199369626
191,0.083105455,32.12166044,473.7010948,0.189403933
191.25,0.082841893,26.37186635,472.1987891,0.15550053
191.5,0.082562423,20.19767196,470.6058091,0.119094669
191.75,0.082410811,18.95114072,469.741624,0.111744553
192,0.082318093,22.63440424,469.2131325,0.133462752
192.25,0.08200757,20.96110858,467.4431498,0.123596239
192.5,0.081884569,17.80261536,466.7420443,0.104972325
192.75,0.081589995,14.58550332,465.0629735,0.086002768
193,0.081362043,12.05005555,463.7636468,0.071052613
193.25,0.081094218,9.657812108,462.2370421,0.056946857
193.5,0.080971309,11.92271321,461.5364613,0.070301745
193.75,0.080741662,12.23272979,460.2274716,0.072129744
194,0.080626931,8.794823405,459.5735039,0.051858283
194.25,0.080511252,10.00291914,458.9141373,0.058981765
194.5,0.080086896,6.376211691,456.4953046,0.037597047
194.75,0.079848985,5.409074249,455.1392163,0.031894364
195,0.079502707,6.24576886,453.165432,0.036827897
195.25,0.07925941,3.742876334,451.7786398,0.022069703
195.5,0.079154354,3.125901594,451.1798164,0.018431739
195.75,0.078959409,2.918909823,450.0686308,0.017211221
196,0.078870583,2.930135107,449.5623237,0.017277411
196.25,0.078587789,1.754644076,447.9503961,0.01034618
196.5,0.07840584,2.681892661,446.9132888,0.01581366
196.75,0.078176111,1.439488968,445.6038324,0.008487882
197,0.078020349,2.167762975,444.7159868,0.012782117
197.25,0.07772689,0.946093874,443.0432726,0.0055786
197.5,0.077456883,-0.542993338,441.5042324,-0.003201736
197.75,0.077337646,0.361195279,440.8245841,0.002129772
198,0.077071901,-0.21312821,439.3098385,-0.001256701
198.25,0.076740407,0.291696649,437.4203195,0.001719976
198.5,0.076737757,0.835103352,437.4052148,0.00492415
198.75,0.076330599,-0.208848973,435.0844143,-0.001231469
199,0.076247941,-0.892058141,434.6132627,-0.005259981
199.25,0.076378055,0.512396126,435.3549111,0.003021321
199.5,0.076210415,-0.336767297,434.3993679,-0.001985733
199.75,0.076292858,-0.308121079,434.8692921,-0.001816822
200,0.076168105,-0.426767983,434.1582013,-0.002516418
200.25,0.076029233,-0.083440409,433.3666308,-0.000492003
200.5,0.076056674,0.328059404,433.5230441,0.001934388
200.75,0.076145887,-0.512693912,434.0315587,-0.003023077
201,0.076131637,-0.198859844,433.9503291,-0.001172568
201.25,0.076130256,0.001922249,433.9424597,1.13E-05
201.5,0.076200657,0.986297543,434.3437426,0.005815659
201.65,0.076080881,0.098224584,433.6610222,0.000579177